# 起因

Spring默认事务环境下，在serviceA方法中调用了serviceB的测试方法采集数据，并catch住，目的是防止test异常中断biz。伪代码如下。

```java
// ServiceA.class
@Transactional
public void biz(){
    // 省略业务代码
    try{
    	serviceB.test();
    } catch(Throable t){
        log.error("[...]异常", t);
    }
    // 省略业务代码
}
// ServiceB.class
@Transactional
public void collect(){
    // 执行测试代码
}
```

运行过程中，#biz()调用#collect()，#collect()方法执行异常，biz继续执行，但biz提交事务时却抛出了

```java
org.springframework.transaction.UnexpectedRollbackException: Transaction silently rolled back because it has been marked as rollback-only
```

大意就是事务已经被标记为rollback-only，为啥？

# 分析

两个方法都标注了@Transactional开启事务，按照默认隔离级别REQUIRED，两方法在同一个事务中运行。

按本人以往的知识面来说biz声明事务并执行时，并没有catch到已经被biz捕获的异常，因而不会被test抛出的异常中断。

那么何时设的rollback-only？

直接看事务拦截器源码**TransactionInterceptor**

```java
package org.springframework.transaction.interceptor;
public class TransactionInterceptor extends TransactionAspectSupport implements MethodInterceptor, Serializable {

	@Override
	@Nullable
	public Object invoke(MethodInvocation invocation) throws Throwable {
		// Work out the target class: may be {@code null}.
		// The TransactionAttributeSource should be passed the target class
		// as well as the method, which may be from an interface.
		Class<?> targetClass = (invocation.getThis() != null ? AopUtils.getTargetClass(invocation.getThis()) : null);

		// Adapt to TransactionAspectSupport's invokeWithinTransaction...
		return invokeWithinTransaction(invocation.getMethod(), targetClass, invocation::proceed);
	}
}
```

调用父类TransactionAspectSupport的#invokeWithinTransaction()

```java
package org.springframework.transaction.interceptor;
public abstract class TransactionAspectSupport implements BeanFactoryAware, InitializingBean {

	protected Object invokeWithinTransaction(Method method, @Nullable Class<?> targetClass,
			final InvocationCallback invocation) throws Throwable {

		// If the transaction attribute is null, the method is non-transactional.
		TransactionAttributeSource tas = getTransactionAttributeSource();
		final TransactionAttribute txAttr = (tas != null ? tas.getTransactionAttribute(method, targetClass) : null);
		final PlatformTransactionManager tm = determineTransactionManager(txAttr);
		final String joinpointIdentification = methodIdentification(method, targetClass, txAttr);

		if (txAttr == null || !(tm instanceof CallbackPreferringPlatformTransactionManager)) {
			// Standard transaction demarcation with getTransaction and commit/rollback calls.
			TransactionInfo txInfo = createTransactionIfNecessary(tm, txAttr, joinpointIdentification);

			Object retVal;
			try {
				// This is an around advice: Invoke the next interceptor in the chain.
				// This will normally result in a target object being invoked.
				retVal = invocation.proceedWithInvocation();
			}
			catch (Throwable ex) {
				// target invocation exception
				completeTransactionAfterThrowing(txInfo, ex);
				throw ex;
			}
			finally {
				cleanupTransactionInfo(txInfo);
			}
			commitTransactionAfterReturning(txInfo);
			return retVal;
		}

		else {
			Object result;
			final ThrowableHolder throwableHolder = new ThrowableHolder();

			// It's a CallbackPreferringPlatformTransactionManager: pass a TransactionCallback in.
            // 省略，关系不大，用户自定义的事务回调
		}
	}
}
```

经过断点调试，发现test抛出的异常仍旧被catch捕获了，并在#completeTransactionAfterThrowing()方法中标记了rollback-only，回溯堆栈正是调用test方法地址的时候，那么以往的知识点应该可以推翻了。

那么问题转移，为何执行同一个事务的方法时，后续接口依旧会走到拦截器中？事务不是已经在第一个@Transactional时就已经声明了吗？

TransactionInterceptor实现**MethodInterceptor**和**Interceptor**。

